Workbook

Sheet MODELOPRONOSTICO
B2: Trabajo de campo- Modelo de Pronóstico para la demanda de energia electrica en Tucuman en 2027
A6: Fecha | B6: Demanda GWh | C6: Temp | D6: Temp^2 | E6: Nivel (L) | F6: Tendencia (T) | G6: Estaci (S) | H6: Pron (F) | I6: ERROR GWh | J6: ERROR ABS | K6: t | L6: MAPE
A7: Jan-19 | B7: 261.36 | C7: 25 | D7: =POWER(C7,2) -> 625 | E7: =$O$8+($O$9*C7)+($O$10*D7) -> 262.95167 | F7: =$O$11*K7 -> 0 | G7: =$O$15 -> 0 | H7: =E7+F7+G7 -> 262.95167 | I7: =B7-H7 -> -1.5916744 | J7: =ABS(I7) -> 1.5916744 | K7: 0 | L7: =J7/B7 -> 0.0060899694
A8: Feb-19 | B8: 241.24 | C8: 24.1 | D8: =POWER(C8,2) -> 580.81 | E8: =$O$8+($O$9*C8)+($O$10*D8) -> 247.0793 | F8: =$O$11*K8 -> 0.39568717 | G8: =$O$16 -> -13.718213 | H8: =E8+F8+G8 -> 233.75677 | I8: =B8-H8 -> 7.4832272 | J8: =ABS(I8) -> 7.4832272 | K8: 1 | L8: =J8/B8 -> 0.031019844 | N8: β0 | O8: 538.23404
A9: Mar-19 | B9: 207.37 | C9: 21.2 | D9: =POWER(C9,2) -> 449.44 | E9: =$O$8+($O$9*C9)+($O$10*D9) -> 209.03427 | F9: =$O$11*K9 -> 0.79137434 | G9: =$O$17 -> 7.4896918 | H9: =E9+F9+G9 -> 217.31533 | I9: =B9-H9 -> -9.9453322 | J9: =ABS(I9) -> 9.9453322 | K9: 2 | L9: =J9/B9 -> 0.047959359 | N9: β1 | O9: -40.728378 | Q9: MAD | R9: =AVERAGE(J7:J90) -> 8.4339882
A10: Apr-19 | B10: 189.23 | C10: 19.7 | D10: =POWER(C10,2) -> 388.09 | E10: =$O$8+($O$9*C10)+($O$10*D10) -> 197.20111 | F10: =$O$11*K10 -> 1.1870615 | G10: =$O$18 -> -15.674954 | H10: =E10+F10+G10 -> 182.71322 | I10: =B10-H10 -> 6.5167821 | J10: =ABS(I10) -> 6.5167821 | K10: 3 | L10: =J10/B10 -> 0.034438419 | N10: β2 | O10: 1.1886833 | Q10: MAPE | R10: =AVERAGE(L7:L90) -> 0.034041515
A11: May-19 | B11: 199.29 | C11: 16 | D11: =POWER(C11,2) -> 256 | E11: =$O$8+($O$9*C11)+($O$10*D11) -> 190.88293 | F11: =$O$11*K11 -> 1.5827487 | G11: =$O$19 -> -3.0721556 | H11: =E11+F11+G11 -> 189.39352 | I11: =B11-H11 -> 9.8964784 | J11: =ABS(I11) -> 9.8964784 | K11: 4 | L11: =J11/B11 -> 0.04965868 | N11: β3 | O11: 0.39568717
A12: Jun-19 | B12: 203.55 | C12: 14.6 | D12: =POWER(C12,2) -> 213.16 | E12: =$O$8+($O$9*C12)+($O$10*D12) -> 196.97946 | F12: =$O$11*K12 -> 1.9784358 | G12: =$O$20 -> -4.0964885 | H12: =E12+F12+G12 -> 194.86141 | I12: =B12-H12 -> 8.6885888 | J12: =ABS(I12) -> 8.6885888 | K12: 5 | L12: =J12/B12 -> 0.04268528
A13: Jul-19 | B13: 220.64 | C13: 11.7 | D13: =POWER(C13,2) -> 136.89 | E13: =$O$8+($O$9*C13)+($O$10*D13) -> 224.43088 | F13: =$O$11*K13 -> 2.374123 | G13: =$O$21 -> -0.089372752 | H13: =E13+F13+G13 -> 226.71563 | I13: =B13-H13 -> -6.0756325 | J13: =ABS(I13) -> 6.0756325 | K13: 6 | L13: =J13/B13 -> 0.027536405
A14: Aug-19 | B14: 204.59 | C14: 12.4 | D14: =POWER(C14,2) -> 153.76 | E14: =$O$8+($O$9*C14)+($O$10*D14) -> 215.97411 | F14: =$O$11*K14 -> 2.7698102 | G14: =$O$22 -> -13.564531 | H14: =E14+F14+G14 -> 205.17938 | I14: =B14-H14 -> -0.58938484 | J14: =ABS(I14) -> 0.58938484 | K14: 7 | L14: =J14/B14 -> 0.0028808096 | N14: Dummies | O14: Valor
A15: Sep-19 | B15: 192.14 | C15: 15.4 | D15: =POWER(C15,2) -> 237.16 | E15: =$O$8+($O$9*C15)+($O$10*D15) -> 192.92516 | F15: =$O$11*K15 -> 3.1654974 | G15: =$O$23 -> -10.740128 | H15: =E15+F15+G15 -> 185.35053 | I15: =B15-H15 -> 6.7894696 | J15: =ABS(I15) -> 6.7894696 | K15: 8 | L15: =J15/B15 -> 0.035336055 | N15: Ene | O15: 0 | R15: Resumen
A16: Oct-19 | B16: 227.14 | C16: 17.5 | D16: =POWER(C16,2) -> 306.25 | E16: =$O$8+($O$9*C16)+($O$10*D16) -> 189.5217 | F16: =$O$11*K16 -> 3.5611845 | G16: =$O$24 -> 19.240871 | H16: =E16+F16+G16 -> 212.32375 | I16: =B16-H16 -> 14.816245 | J16: =ABS(I16) -> 14.816245 | K16: 9 | L16: =J16/B16 -> 0.065229574 | N16: Feb | O16: -13.718213
A17: Nov-19 | B17: 248.91 | C17: 22.7 | D17: =POWER(C17,2) -> 515.29 | E17: =$O$8+($O$9*C17)+($O$10*D17) -> 226.2165 | F17: =$O$11*K17 -> 3.9568717 | G17: =$O$25 -> 17.014535 | H17: =E17+F17+G17 -> 247.1879 | I17: =B17-H17 -> 1.7220967 | J17: =ABS(I17) -> 1.7220967 | K17: 10 | L17: =J17/B17 -> 0.0069185518 | N17: Mar | O17: 7.4896918 | R17: Estadísticas de la regresión
A18: Dec-19 | B18: 271.93 | C18: 23.7 | D18: =POWER(C18,2) -> 561.69 | E18: =$O$8+($O$9*C18)+($O$10*D18) -> 240.64302 | F18: =$O$11*K18 -> 4.3525589 | G18: =$O$26 -> 22.117013 | H18: =E18+F18+G18 -> 267.1126 | I18: =B18-H18 -> 4.8174038 | J18: =ABS(I18) -> 4.8174038 | K18: 11 | L18: =J18/B18 -> 0.017715602 | N18: Abr | O18: -15.674954 | R18: Coeficiente de correlación múltiple | S18: 0.94984255
A19: Jan-20 | B19: 285.09 | C19: 25.1 | D19: =POWER(C19,2) -> 630.01 | E19: =$O$8+($O$9*C19)+($O$10*D19) -> 264.83414 | F19: =$O$11*K19 -> 4.748246 | G19: =$O$15 -> 0 | H19: =E19+F19+G19 -> 269.58239 | I19: =B19-H19 -> 15.507614 | J19: =ABS(I19) -> 15.507614 | K19: 12 | L19: =J19/B19 -> 0.054395503 | N19: May | O19: -3.0721556 | R19: Coeficiente de determinación R^2 | S19: 0.90220087
A20: Feb-20 | B20: 232.23 | C20: 25.5 | D20: =POWER(C20,2) -> 650.25 | E20: =$O$8+($O$9*C20)+($O$10*D20) -> 272.60174 | F20: =$O$11*K20 -> 5.1439332 | G20: =$O$16 -> -13.718213 | H20: =E20+F20+G20 -> 264.02746 | I20: =B20-H20 -> -31.79746 | J20: =ABS(I20) -> 31.79746 | K20: 13 | L20: =J20/B20 -> 0.13692227 | N20: Jun | O20: -4.0964885 | R20: R^2 ajustado | S20: 0.88235757
A21: Mar-20 | B21: 265.17 | C21: 24.4 | D21: =POWER(C21,2) -> 595.36 | E21: =$O$8+($O$9*C21)+($O$10*D21) -> 252.15613 | F21: =$O$11*K21 -> 5.5396204 | G21: =$O$17 -> 7.4896918 | H21: =E21+F21+G21 -> 265.18544 | I21: =B21-H21 -> -0.015439653 | J21: =ABS(I21) -> 0.015439653 | K21: 14 | L21: =J21/B21 -> 5.822549e-05 | N21: Jul | O21: -0.089372752 | R21: Error típico | S21: 13.523378
A22: Apr-20 | B22: 184.11 | C22: 18 | D22: =POWER(C22,2) -> 324 | E22: =$O$8+($O$9*C22)+($O$10*D22) -> 190.25664 | F22: =$O$11*K22 -> 5.9353075 | G22: =$O$18 -> -15.674954 | H22: =E22+F22+G22 -> 180.51699 | I22: =B22-H22 -> 3.593008 | J22: =ABS(I22) -> 3.593008 | K22: 15 | L22: =J22/B22 -> 0.01951555 | N22: Ago | O22: -13.564531 | R22: Observaciones | S22: 84
A23: May-20 | B23: 188.35 | C23: 15.7 | D23: =POWER(C23,2) -> 246.49 | E23: =$O$8+($O$9*C23)+($O$10*D23) -> 191.79706 | F23: =$O$11*K23 -> 6.3309947 | G23: =$O$19 -> -3.0721556 | H23: =E23+F23+G23 -> 195.0559 | I23: =B23-H23 -> -6.7059026 | J23: =ABS(I23) -> 6.7059026 | K23: 16 | L23: =J23/B23 -> 0.035603412 | N23: Sep | O23: -10.740128
A24: Jun-20 | B24: 205.22 | C24: 13 | D24: =POWER(C24,2) -> 169 | E24: =$O$8+($O$9*C24)+($O$10*D24) -> 209.65261 | F24: =$O$11*K24 -> 6.7266819 | G24: =$O$20 -> -4.0964885 | H24: =E24+F24+G24 -> 212.28281 | I24: =B24-H24 -> -7.0628061 | J24: =ABS(I24) -> 7.0628061 | K24: 17 | L24: =J24/B24 -> 0.034415778 | N24: Oct | O24: 19.240871 | R24: ANÁLISIS DE VARIANZA
A25: Jul-20 | B25: 233.79 | C25: 10.9 | D25: =POWER(C25,2) -> 118.81 | E25: =$O$8+($O$9*C25)+($O$10*D25) -> 235.52219 | F25: =$O$11*K25 -> 7.122369 | G25: =$O$21 -> -0.089372752 | H25: =E25+F25+G25 -> 242.55519 | I25: =B25-H25 -> -8.7651862 | J25: =ABS(I25) -> 8.7651862 | K25: 18 | L25: =J25/B25 -> 0.037491707 | N25: Nov | O25: 17.014535 | S25: Grados de libertad | T25: Suma de cuadrados | U25: Promedio de los cuadrados | V25: F | W25: Valor crítico de F
A26: Aug-20 | B26: 199.99 | C26: 13.1 | D26: =POWER(C26,2) -> 171.61 | E26: =$O$8+($O$9*C26)+($O$10*D26) -> 208.68224 | F26: =$O$11*K26 -> 7.5180562 | G26: =$O$22 -> -13.564531 | H26: =E26+F26+G26 -> 202.63576 | I26: =B26-H26 -> -2.6457638 | J26: =ABS(I26) -> 2.6457638 | K26: 19 | L26: =J26/B26 -> 0.01322948 | N26: Dic | O26: 22.117013 | R26: Regresión | S26: 14 | T26: 116409.32 | U26: 8314.9515 | V26: 45.466268 | W26: 3.3505142e-29
A27: Sep-20 | B27: 194.21 | C27: 14.6 | D27: =POWER(C27,2) -> 213.16 | E27: =$O$8+($O$9*C27)+($O$10*D27) -> 196.97946 | F27: =$O$11*K27 -> 7.9137434 | G27: =$O$23 -> -10.740128 | H27: =E27+F27+G27 -> 194.15308 | I27: =B27-H27 -> 0.056921145 | J27: =ABS(I27) -> 0.056921145 | K27: 20 | L27: =J27/B27 -> 0.0002930907 | R27: Residuos | S27: 69 | T27: 12618.842 | U27: 182.88177
A28: Oct-20 | B28: 224.49 | C28: 17.2 | D28: =POWER(C28,2) -> 295.84 | E28: =$O$8+($O$9*C28)+($O$10*D28) -> 189.36602 | F28: =$O$11*K28 -> 8.3094305 | G28: =$O$24 -> 19.240871 | H28: =E28+F28+G28 -> 216.91632 | I28: =B28-H28 -> 7.5736795 | J28: =ABS(I28) -> 7.5736795 | K28: 21 | L28: =J28/B28 -> 0.033737269 | R28: Total | S28: 83 | T28: 129028.16
A29: Nov-20 | B29: 244.96 | C29: 21.9 | D29: =POWER(C29,2) -> 479.61 | E29: =$O$8+($O$9*C29)+($O$10*D29) -> 216.38698 | F29: =$O$11*K29 -> 8.7051177 | G29: =$O$25 -> 17.014535 | H29: =E29+F29+G29 -> 242.10663 | I29: =B29-H29 -> 2.8533694 | J29: =ABS(I29) -> 2.8533694 | K29: 22 | L29: =J29/B29 -> 0.011648307
A30: Dec-20 | B30: 279.84 | C30: 23.5 | D30: =POWER(C30,2) -> 552.25 | E30: =$O$8+($O$9*C30)+($O$10*D30) -> 237.56753 | F30: =$O$11*K30 -> 9.1008049 | G30: =$O$26 -> 22.117013 | H30: =E30+F30+G30 -> 268.78535 | I30: =B30-H30 -> 11.054653 | J30: =ABS(I30) -> 11.054653 | K30: 23 | L30: =J30/B30 -> 0.039503476 | S30: Coeficientes | T30: Error típico | U30: Estadístico t | V30: Probabilidad | W30: Inferior 95% | X30: Superior 95% | Y30: Inferior 95,0% | Z30: Superior 95,0%
A31: Jan-21 | B31: 261.85 | C31: 25.5 | D31: =POWER(C31,2) -> 650.25 | E31: =$O$8+($O$9*C31)+($O$10*D31) -> 272.60174 | F31: =$O$11*K31 -> 9.4964921 | G31: =$O$15 -> 0 | H31: =E31+F31+G31 -> 282.09823 | I31: =B31-H31 -> -20.248231 | J31: =ABS(I31) -> 20.248231 | K31: 24 | L31: =J31/B31 -> 0.077327598 | R31: Intercepción | S31: 538.23404 | T31: 57.625666 | U31: 9.340179 | V31: 7.1999665e-14 | W31: 423.27398 | X31: 653.1941 | Y31: 423.27398 | Z31: 653.1941
A32: Feb-21 | B32: 211.49 | C32: 23.6 | D32: =POWER(C32,2) -> 556.96 | E32: =$O$8+($O$9*C32)+($O$10*D32) -> 239.09339 | F32: =$O$11*K32 -> 9.8921792 | G32: =$O$16 -> -13.718213 | H32: =E32+F32+G32 -> 235.26736 | I32: =B32-H32 -> -23.777357 | J32: =ABS(I32) -> 23.777357 | K32: 25 | L32: =J32/B32 -> 0.11242781 | R32: t | S32: 0.39568717 | T32: 0.063083571 | U32: 6.2724282 | V32: 2.6938403e-08 | W32: 0.26983889 | X32: 0.52153545 | Y32: 0.26983889 | Z32: 0.52153545
A33: Mar-21 | B33: 223.69 | C33: 22.2 | D33: =POWER(C33,2) -> 492.84 | E33: =$O$8+($O$9*C33)+($O$10*D33) -> 219.89474 | F33: =$O$11*K33 -> 10.287866 | G33: =$O$17 -> 7.4896918 | H33: =E33+F33+G33 -> 237.6723 | I33: =B33-H33 -> -13.982303 | J33: =ABS(I33) -> 13.982303 | K33: 26 | L33: =J33/B33 -> 0.0625075 | R33: Temp | S33: -40.728378 | T33: 5.4322472 | U33: -7.4975192 | V33: 1.6559412e-10 | W33: -51.565414 | X33: -29.891341 | Y33: -51.565414 | Z33: -29.891341
A34: Apr-21 | B34: 194.39 | C34: 20.7 | D34: =POWER(C34,2) -> 428.49 | E34: =$O$8+($O$9*C34)+($O$10*D34) -> 204.49554 | F34: =$O$11*K34 -> 10.683554 | G34: =$O$18 -> -15.674954 | H34: =E34+F34+G34 -> 199.50414 | I34: =B34-H34 -> -5.1141384 | J34: =ABS(I34) -> 5.1141384 | K34: 27 | L34: =J34/B34 -> 0.02630865 | R34: Temp^2 | S34: 1.1886833 | T34: 0.13513455 | U34: 8.7962943 | V34: 7.0110611e-13 | W34: 0.91909726 | X34: 1.4582694 | Y34: 0.91909726 | Z34: 1.4582694
A35: May-21 | B35: 198.08 | C35: 14.3 | D35: =POWER(C35,2) -> 204.49 | E35: =$O$8+($O$9*C35)+($O$10*D35) -> 198.89209 | F35: =$O$11*K35 -> 11.079241 | G35: =$O$19 -> -3.0721556 | H35: =E35+F35+G35 -> 206.89918 | I35: =B35-H35 -> -8.8191779 | J35: =ABS(I35) -> 8.8191779 | K35: 28 | L35: =J35/B35 -> 0.044523313 | R35: Feb | S35: -13.718213 | T35: 7.4542212 | U35: -1.8403281 | V35: 0.070020653 | W35: -28.588977 | X35: 1.1525516 | Y35: -28.588977 | Z35: 1.1525516
A36: Jun-21 | B36: 232.77 | C36: 11.9 | D36: =POWER(C36,2) -> 141.61 | E36: =$O$8+($O$9*C36)+($O$10*D36) -> 221.89579 | F36: =$O$11*K36 -> 11.474928 | G36: =$O$20 -> -4.0964885 | H36: =E36+F36+G36 -> 229.27423 | I36: =B36-H36 -> 3.4957686 | J36: =ABS(I36) -> 3.4957686 | K36: 29 | L36: =J36/B36 -> 0.015018124 | R36: Mar | S36: 7.4896918 | T36: 8.6324258 | U36: 0.86762308 | V36: 0.38860819 | W36: -9.7315265 | X36: 24.71091 | Y36: -9.7315265 | Z36: 24.71091
A37: Jul-21 | B37: 227.66 | C37: 12.2 | D37: =POWER(C37,2) -> 148.84 | E37: =$O$8+($O$9*C37)+($O$10*D37) -> 218.27146 | F37: =$O$11*K37 -> 11.870615 | G37: =$O$21 -> -0.089372752 | H37: =E37+F37+G37 -> 230.0527 | I37: =B37-H37 -> -2.3927014 | J37: =ABS(I37) -> 2.3927014 | K37: 30 | L37: =J37/B37 -> 0.010509977 | R37: Abr | S37: -15.674954 | T37: 12.911045 | U37: -1.2140732 | V37: 0.22885883 | W37: -41.431785 | X37: 10.081876 | Y37: -41.431785 | Z37: 10.081876
A38: Aug-21 | B38: 210.21 | C38: 13.2 | D38: =POWER(C38,2) -> 174.24 | E38: =$O$8+($O$9*C38)+($O$10*D38) -> 207.73564 | F38: =$O$11*K38 -> 12.266302 | G38: =$O$22 -> -13.564531 | H38: =E38+F38+G38 -> 206.43741 | I38: =B38-H38 -> 3.7725908 | J38: =ABS(I38) -> 3.7725908 | K38: 31 | L38: =J38/B38 -> 0.017946771 | R38: May | S38: -3.0721556 | T38: 16.350926 | U38: -0.18788878 | V38: 0.85151529 | W38: -35.691361 | X38: 29.54705 | Y38: -35.691361 | Z38: 29.54705
A39: Sep-21 | B39: 193.99 | C39: 16 | D39: =POWER(C39,2) -> 256 | E39: =$O$8+($O$9*C39)+($O$10*D39) -> 190.88293 | F39: =$O$11*K39 -> 12.661989 | G39: =$O$23 -> -10.740128 | H39: =E39+F39+G39 -> 192.80479 | I39: =B39-H39 -> 1.1852104 | J39: =ABS(I39) -> 1.1852104 | K39: 32 | L39: =J39/B39 -> 0.0061096469 | R39: Jun | S39: -4.0964885 | T39: 18.998832 | U39: -0.21561791 | V39: 0.82992169 | W39: -41.998121 | X39: 33.805144 | Y39: -41.998121 | Z39: 33.805144
A40: Oct-21 | B40: 234.73 | C40: 18.8 | D40: =POWER(C40,2) -> 353.44 | E40: =$O$8+($O$9*C40)+($O$10*D40) -> 192.66877 | F40: =$O$11*K40 -> 13.057677 | G40: =$O$24 -> 19.240871 | H40: =E40+F40+G40 -> 224.96732 | I40: =B40-H40 -> 9.7626785 | J40: =ABS(I40) -> 9.7626785 | K40: 33 | L40: =J40/B40 -> 0.041591098 | R40: Jul | S40: -0.089372752 | T40: 20.189031 | U40: -0.0044267975 | V40: 0.99648071 | W40: -40.365388 | X40: 40.186642 | Y40: -40.365388 | Z40: 40.186642
A41: Nov-21 | B41: 231.8 | C41: 21.6 | D41: =POWER(C41,2) -> 466.56 | E41: =$O$8+($O$9*C41)+($O$10*D41) -> 213.09317 | F41: =$O$11*K41 -> 13.453364 | G41: =$O$25 -> 17.014535 | H41: =E41+F41+G41 -> 243.56107 | I41: =B41-H41 -> -11.761073 | J41: =ABS(I41) -> 11.761073 | K41: 34 | L41: =J41/B41 -> 0.050738018 | R41: Ago | S41: -13.564531 | T41: 18.320617 | U41: -0.74039703 | V41: 0.46157116 | W41: -50.113163 | X41: 22.984101 | Y41: -50.113163 | Z41: 22.984101
A42: Dec-21 | B42: 288.91 | C42: 25 | D42: =POWER(C42,2) -> 625 | E42: =$O$8+($O$9*C42)+($O$10*D42) -> 262.95167 | F42: =$O$11*K42 -> 13.849051 | G42: =$O$26 -> 22.117013 | H42: =E42+F42+G42 -> 298.91774 | I42: =B42-H42 -> -10.007738 | J42: =ABS(I42) -> 10.007738 | K42: 35 | L42: =J42/B42 -> 0.034639639 | R42: Sep | S42: -10.740128 | T42: 15.906545 | U42: -0.67520183 | V42: 0.50180399 | W42: -42.472818 | X42: 20.992561 | Y42: -42.472818 | Z42: 20.992561
A43: Jan-22 | B43: 317.12 | C43: 26.2 | D43: =POWER(C43,2) -> 686.44 | E43: =$O$8+($O$9*C43)+($O$10*D43) -> 287.11032 | F43: =$O$11*K43 -> 14.244738 | G43: =$O$15 -> 0 | H43: =E43+F43+G43 -> 301.35506 | I43: =B43-H43 -> 15.764938 | J43: =ABS(I43) -> 15.764938 | K43: 36 | L43: =J43/B43 -> 0.049712846 | R43: Oct | S43: 19.240871 | T43: 13.331392 | U43: 1.4432754 | V43: 0.15346772 | W43: -7.3545292 | X43: 45.836271 | Y43: -7.3545292 | Z43: 45.836271
A44: Feb-22 | B44: 234.96 | C44: 23.2 | D44: =POWER(C44,2) -> 538.24 | E44: =$O$8+($O$9*C44)+($O$10*D44) -> 233.13259 | F44: =$O$11*K44 -> 14.640425 | G44: =$O$16 -> -13.718213 | H44: =E44+F44+G44 -> 234.0548 | I44: =B44-H44 -> 0.90519812 | J44: =ABS(I44) -> 0.90519812 | K44: 37 | L44: =J44/B44 -> 0.0038525626 | R44: Nov | S44: 17.014535 | T44: 10.166381 | U44: 1.6736078 | V44: 0.098735638 | W44: -3.2668405 | X44: 37.295911 | Y44: -3.2668405 | Z44: 37.295911
...

Sheet DemandaERenovables
A2: Parámetros de Energía Renovable EXTRAÍDO DEL EXCEL CAMMESA
A5: HIDRO <= 50Mw (GWh) | E5: σ_ε | F5: =MODELOPRONOSTICO!S21 -> 13.523378 | G5: (Proviene del pronostico)
A7: Mes | B7: Ene | C7: Feb | D7: Mar | E7: Abr | F7: May | G7: Jun | H7: Jul | I7: Ago | J7: Sep | K7: Oct | L7: Nov | M7: Dic
A8: E[Ghidro,t] | B8: 9.16 | C8: 10.6 | D8: 16.7 | E8: 12.7 | F8: 6.17 | G8: 4.8 | H8: 5.41 | I8: 7.36 | J8: 9.31 | K8: 10.42 | L8: 9.86 | M8: 10.73
A9: σren,HIDRO,t | B9: 4.03 | C9: 5.3 | D9: 9.12 | E9: 3.16 | F9: 1.79 | G9: 1.55 | H9: 0.77 | I9: 0.46 | J9: 0.66 | K9: 1.81 | L9: 4.17 | M9: 5.33
A10: G max HIDRO,t | B10: 14.82 | C10: 14.84 | D10: 27.58 | E10: 18.15 | F10: 8.33 | G10: 6.01 | H10: 6.18 | I10: 7.81 | J10: 10.24 | K10: 13.91 | L10: 17.78 | M10: 19.7
A13: BIOMASA (GWh)
A15: Mes | B15: Ene | C15: Feb | D15: Mar | E15: Abr | F15: May | G15: Jun | H15: Jul | I15: Ago | J15: Sep | K15: Oct | L15: Nov | M15: Dic
A16: E[Gbm,t] | B16: 0 | C16: 0 | D16: 0 | E16: 0.09 | F16: 2.34 | G16: 5.54 | H16: 7.28 | I16: 7.22 | J16: 5.56 | K16: 4.24 | L16: 2.08 | M16: 0.24
A17: σren,BM,t | B17: 0 | C17: 0 | D17: 0 | E17: 0.22 | F17: 1.82 | G17: 3.23 | H17: 2.12 | I17: 1.59 | J17: 1.36 | K17: 2 | L17: 1.61 | M17: 0.39
A18: G max BM,t | B18: 0 | C18: 0 | D18: 0 | E18: 0.54 | F18: 5.92 | G18: 11.49 | H18: 10.67 | I18: 10.17 | J18: 8.07 | K18: 7.47 | L18: 4.82 | M18: 0.91
A21: BIOGAS (GWh)
A23: Mes | B23: Ene | C23: Feb | D23: Mar | E23: Abr | F23: May | G23: Jun | H23: Jul | I23: Ago | J23: Sep | K23: Oct | L23: Nov | M23: Dic
A24: E[Gbg,t] | B24: 0.15 | C24: 0.13 | D24: 0.18 | E24: 0.61 | F24: 1.56 | G24: 1.55 | H24: 1.41 | I24: 1.53 | J24: 0.79 | K24: 0.36 | L24: 0.38 | M24: 0.28
A25: σren,BG,t | B25: 0.2 | C25: 0.2 | D25: 0.24 | E25: 0.24 | F25: 0.34 | G25: 0.41 | H25: 0.31 | I25: 0.51 | J25: 0.57 | K25: 0.28 | L25: 0.3 | M25: 0.24
A26: G max BG,t | B26: 0.42 | C26: 0.4 | D26: 0.64 | E26: 1.03 | F26: 1.99 | G26: 2.05 | H26: 1.93 | I26: 1.99 | J26: 1.41 | K26: 0.69 | L26: 0.67 | M26: 0.62
A33: Mes | B33: Ene | C33: Feb | D33: Mar | E33: Abr | F33: May | G33: Jun | H33: Jul | I33: Ago | J33: Sep | K33: Oct | L33: Nov | M33: Dic
A34: σt | B34: =SQRT(($F$5^2)+(B9^2)+(B17^2)+(B25^2)) -> 14.1125 | C34: =SQRT(($F$5^2)+(C9^2)+(C17^2)+(C25^2)) -> 14.526244 | D34: =SQRT(($F$5^2)+(D9^2)+(D17^2)+(D25^2)) -> 16.312994 | E34: =SQRT(($F$5^2)+(E9^2)+(E17^2)+(E25^2)) -> 13.891485 | F34: =SQRT(($F$5^2)+(F9^2)+(F17^2)+(F25^2)) -> 13.766404 | G34: =SQRT(($F$5^2)+(G9^2)+(G17^2)+(G25^2)) -> 13.995902 | H34: =SQRT(($F$5^2)+(H9^2)+(H17^2)+(H25^2)) -> 13.713685 | I34: =SQRT(($F$5^2)+(I9^2)+(I17^2)+(I25^2)) -> 13.633839 | ... M34: =SQRT(($F$5^2)+(M9^2)+(M17^2)+(M25^2)) -> 14.543052

Sheet MODELONEWSVENDOR
A2: MODELO NEWSVENDOR
A5: CENS= | B5: 1500000 | C5: UDS/GWh
A7: C_mem | B7: UDS/GWh, estacional
A8: C_mem | B8: Ene | C8: Feb | D8: Mar | E8: Abr | F8: May | G8: Jun | H8: Jul | I8: Ago | J8: Sep | K8: Oct | L8: Nov | M8: Dic
A9: valor | B9: 71900 | C9: 70730 | D9: 70720 | E9: 70470 | F9: 85650 | G9: 97070 | H9: 93790 | I9: 82330 | J9: 76310 | K9: 65670 | L9: 61670 | M9: 56630
A11: Co=C_res = | B11: 1388.89 | C11: UDS/GWh
A25: Columna1 | B25: Ene | C25: Feb | D25: Mar | E25: Abr | F25: May | G25: Jun | H25: Jul | I25: Ago | J25: Sep | K25: Oct | L25: Nov | M25: Dic
A26: C_mem UDS/GWh | B26: 71900 | C26: 70730 | D26: 70720 | E26: 70470 | F26: 85650 | G26: 97070 | H26: 93790 | I26: 82330 | J26: 76310 | K26: 65670 | L26: 61670 | M26: 56630
A27: σt | B27: =DemandaERenovables!B34 -> 14.1125 | C27: =DemandaERenovables!C34 -> 14.526244 | D27: =DemandaERenovables!D34 -> 16.312994 | E27: =DemandaERenovables!E34 -> 13.891485 | F27: =DemandaERenovables!F34 -> 13.766404 | G27: =DemandaERenovables!G34 -> 13.995902 | H27: =DemandaERenovables!H34 -> 13.713685 | I27: =DemandaERenovables!I34 -> 13.633839 | ... M27: =DemandaERenovables!M34 -> 14.543052
A28: C_u (t) | B28: =$B$5-B26 -> 1428100 | C28: =$B$5-C26 -> 1429270 | D28: =$B$5-D26 -> 1429280 | E28: =$B$5-E26 -> 1429530 | F28: =$B$5-F26 -> 1414350 | G28: =$B$5-G26 -> 1402930 | H28: =$B$5-H26 -> 1406210 | I28: =$B$5-I26 -> 1417670 | ... M28: =$B$5-M26 -> 1443370
A29: CR | B29: =B28/(B28+$B$11) -> 0.9990284 | C29: =C28/(C28+$B$11) -> 0.9990292 | D29: =D28/(D28+$B$11) -> 0.9990292 | E29: =E28/(E28+$B$11) -> 0.99902937 | F29: =F28/(F28+$B$11) -> 0.99901896 | G29: =G28/(G28+$B$11) -> 0.99901099 | H29: =H28/(H28+$B$11) -> 0.99901329 | I29: =I28/(I28+$B$11) -> 0.99902126 | ... M29: =M28/(M28+$B$11) -> 0.99903867
A30: Z_t | B30: =NORMSINV(B29) -> 3.0987792 | C30: =NORMSINV(C29) -> 3.0990216 | D30: =NORMSINV(D29) -> 3.0990236 | E30: =NORMSINV(E29) -> 3.0990754 | F30: =NORMSINV(F29) -> 3.0959143 | G30: =NORMSINV(G29) -> 3.0935119 | H30: =NORMSINV(H29) -> 3.094204 | I30: =NORMSINV(I29) -> 3.0966088 | ... M30: =NORMSINV(M29) -> 3.101926
A31: SS_t (GWh) | B31: =B30*B27 -> 43.731522 | C31: =C30*C27 -> 45.017144 | D31: =D30*D27 -> 50.554353 | E31: =E30*E27 -> 43.050761 | F31: =F30*F27 -> 42.619605 | G31: =G30*G27 -> 43.296488 | H31: =H30*H27 -> 42.43294 | I31: =I30*I27 -> 42.218665 | ... M31: =M30*M27 -> 45.111472

Sheet PARAMETROSPL
A2: Parámetros globales del modelo
A5: Parámetro | B5: Valor | C5: Unidad | D5: Valor convertido | E5: Unidad convertida
A6: CENS | B6: 1500 | C6: USD/MWh | D6: 1500000 | E6: USD/GWh | F6: Costo de Energía No Suministrada
A7: C_res (Reserva de Confiabilidad Base) | B7: 1000 | C7: USD/MW-mes | D7: - | E7: - | F7: Costo mensual de mantener contratada una unidad de reserva térmica (costo de exceso del Newsvendor)
A8: horas_mes (supuesto) | B8: 720 | C8: hs/mes | D8: - | E8: - | F8: 30 dias * 24hs, usada para convertir energía en potencia media
A9: eta (pérdidas de transporte) | B9: 0.035 | C9: adim (%) | D9: - | E9: - | F9: Porcentaje de la energía generada que se pierde en el trayecto hasta el usuario final
A10: T_max (línea El Bracho-Cobos) | B10: 1150 | C10: MVA | D10: - | E10: - | F10: Capacidad máxima de transporte de la línea de alta tensión que abastece a Tucumán expresada en potencia aparente
A11: fp (factor de potencia, supuesto) | B11: 0.97 | C11: adim | D11: - | E11: - | F11: Relación entre la potencia activa realmente utilizable y la potenci aparente total de la línea
A12: C_HIDRO (PAH) | B12: 101.93 | C12: USD/MWh | D12: 101930 | E12: USD/GWh | F12: Costo promedio de compra de energía renovable hidroeléctrica de pequeña escala, según contratos de abastecimiento (PAH)
A13: C_BIOMASA (BM) | B13: 124.37 | C13: USD/MWh | D13: 124370 | E13: USD/GWh | F13: Costo promedio de compra de energía renovable generada a partir de biomasa
A14: C_BIOGAS (BG) | B14: 159.42 | C14: USD/MWh | D14: 159420 | E14: USD/GWh | F14: Costo promedio de compra de energía renovable generada a partis de biogás
A15: sigma_epsilon (error residual demanda) | B15: =MODELOPRONOSTICO!S21 -> 13.523378 | C15: GWh | D15: - | E15: - | F15: Desvío estándar del error del modelo de pronóstico, mide cuánto se equivoca en promedio la predicción de demand. Es insumo de variabilidad del módulo Newsvendor
A16: GWh_a_MWh (factor de conversión) | B16: 1000 | C16: MWh/GWh | F16: Factor fijo para convertir en GWh a MWh
A19: Parámetro | B19: Valor | C19: Unidad | D19: Valor convertido | E19: Unidad convertida
A20: C_res_equiv (=C_res / horas_mes) | B20: 1.3889 | C20: USD/MWh | D20: 1388.89 | E20: USD/GWh | F20: Costo de reserva, convertido de USD/MW-mes a USD/MWh
A21: T_max_MW (=T_max_MVA x fp) | B21: =B10*B11 -> 1115.5 | C21: MW | F21: Capacidad de transporte de la línea, convertida de potencia aparente MVA a potencia activa MW aplicando el factor de potencia
A22: T_max_mensual (=T_max_MW x horas_mes / 1000) | B22: =B21*B8/1000 -> 803.16 | C22: GWh/mes | F22: Capacidad de transporte máxima, convertida de una potencia instantánea MW a una cantidad de energía que puede transportarse en un mes GWh.

Sheet DATOSMENSUALES
A2: DATOS MENSUALES — Demanda, Oferta Renovable y Newsvendor
A5: Mes | B5: Unidad | C5: Ene | D5: Feb | E5: Mar | F5: Abr | G5: May | H5: Jun | I5: Jul | J5: Ago | K5: Sep | L5: Oct | M5: Nov | N5: Dic
A6: D_t (demanda pronosticada) | B6: GWh | C6: 313 | D6: 281 | E6: 275 | F6: 212 | G6: 226 | H6: 243 | I6: 257 | J6: 229 | K6: 218 | L6: 248 | M6: 271 | N6: 307
A7: C_mem,t (costo monómico) | B7: UDS/GWh | C7: 71900 | D7: 70730 | E7: 70720 | F7: 70470 | G7: 85650 | H7: 97070 | I7: 93790 | J7: 82330 | K7: 76310 | L7: 65670 | M7: 61670 | N7: 56630
A8: σ_ren HIDRO | B8: GWh | C8: 4.03 | D8: 5.3 | E8: 9.12 | F8: 3.16 | G8: 1.79 | H8: 1.55 | I8: 0.77 | J8: 0.46 | K8: 0.66 | L8: 1.81 | M8: 4.17 | N8: 5.33
A9: σ_ren BIOMASA | B9: GWh | C9: 0 | D9: 0 | E9: 0 | F9: 0.22 | G9: 1.82 | H9: 3.23 | I9: 2.12 | J9: 1.59 | K9: 1.36 | L9: 2 | M9: 1.61 | N9: 0.39
A10: σ_ren BIOGAS | B10: GWh | C10: 0.2 | D10: 0.2 | E10: 0.24 | F10: 0.24 | G10: 0.34 | H10: 0.41 | I10: 0.31 | J10: 0.51 | K10: 0.57 | L10: 0.28 | M10: 0.3 | N10: 0.24
A11: σ_t (variabilidad total) | B11: GWh | C11: =SQRT((PARAMETROSPL!$B$15^2)+DATOSMENSUALES!C8^2+DATOSMENSUALES!C9^2+DATOSMENSUALES!C10^2) -> 14.1125 | D11: =SQRT((PARAMETROSPL!$B$15^2)+DATOSMENSUALES!D8^2+DATOSMENSUALES!D9^2+DATOSMENSUALES!D10^2) -> 14.526244 | E11: =SQRT((PARAMETROSPL!$B$15^2)+DATOSMENSUALES!E8^2+DATOSMENSUALES!E9^2+DATOSMENSUALES!E10^2) -> 16.312994 | F11: =SQRT((PARAMETROSPL!$B$15^2)+DATOSMENSUALES!F8^2+DATOSMENSUALES!F9^2+DATOSMENSUALES!F10^2) -> 13.891485 | G11: =SQRT((PARAMETROSPL!$B$15^2)+DATOSMENSUALES!G8^2+DATOSMENSUALES!G9^2+DATOSMENSUALES!G10^2) -> 13.766404 | H11: =SQRT((PARAMETROSPL!$B$15^2)+DATOSMENSUALES!H8^2+DATOSMENSUALES!H9^2+DATOSMENSUALES!H10^2) -> 13.995902 | I11: =SQRT((PARAMETROSPL!$B$15^2)+DATOSMENSUALES!I8^2+DATOSMENSUALES!I9^2+DATOSMENSUALES!I10^2) -> 13.713685 | J11: =SQRT((PARAMETROSPL!$B$15^2)+DATOSMENSUALES!J8^2+DATOSMENSUALES!J9^2+DATOSMENSUALES!J10^2) -> 13.633839 | ... N11: =SQRT((PARAMETROSPL!$B$15^2)+DATOSMENSUALES!N8^2+DATOSMENSUALES!N9^2+DATOSMENSUALES!N10^2) -> 14.543052
A12: C_u,t (costo de subestimar) | B12: UDS/GWh | C12: =PARAMETROSPL!$D$6-C7 -> 1428100 | D12: =PARAMETROSPL!$D$6-D7 -> 1429270 | E12: =PARAMETROSPL!$D$6-E7 -> 1429280 | F12: =PARAMETROSPL!$D$6-F7 -> 1429530 | G12: =PARAMETROSPL!$D$6-G7 -> 1414350 | H12: =PARAMETROSPL!$D$6-H7 -> 1402930 | I12: =PARAMETROSPL!$D$6-I7 -> 1406210 | J12: =PARAMETROSPL!$D$6-J7 -> 1417670 | ... N12: =PARAMETROSPL!$D$6-N7 -> 1443370
A13: C_o (costo de sobreestimar) | B13: UDS/GWh | C13: =PARAMETROSPL!$D$20 -> 1388.89 | D13: =PARAMETROSPL!$D$20 -> 1388.89 | E13: =PARAMETROSPL!$D$20 -> 1388.89 | F13: =PARAMETROSPL!$D$20 -> 1388.89 | G13: =PARAMETROSPL!$D$20 -> 1388.89 | H13: =PARAMETROSPL!$D$20 -> 1388.89 | I13: =PARAMETROSPL!$D$20 -> 1388.89 | J13: =PARAMETROSPL!$D$20 -> 1388.89 | ... N13: =PARAMETROSPL!$D$20 -> 1388.89
A14: CR (razón crítica) | B14: adim | C14: =C12/(C12+C13) -> 0.9990284 | D14: =D12/(D12+D13) -> 0.9990292 | E14: =E12/(E12+E13) -> 0.9990292 | F14: =F12/(F12+F13) -> 0.99902937 | G14: =G12/(G12+G13) -> 0.99901896 | H14: =H12/(H12+H13) -> 0.99901099 | I14: =I12/(I12+I13) -> 0.99901329 | J14: =J12/(J12+J13) -> 0.99902126 | ... N14: =N12/(N12+N13) -> 0.99903867
A15: Z (inversa normal estándar) | B15: adim | C15: =_xlfn.NORM.S.INV(C14) -> 3.0987792 | D15: =_xlfn.NORM.S.INV(D14) -> 3.0990216 | E15: =_xlfn.NORM.S.INV(E14) -> 3.0990236 | F15: =_xlfn.NORM.S.INV(F14) -> 3.0990754 | G15: =_xlfn.NORM.S.INV(G14) -> 3.0959143 | H15: =_xlfn.NORM.S.INV(H14) -> 3.0935119 | I15: =_xlfn.NORM.S.INV(I14) -> 3.094204 | J15: =_xlfn.NORM.S.INV(J14) -> 3.0966088 | ... N15: =_xlfn.NORM.S.INV(N14) -> 3.101926
A16: SS_t (stock de seguridad) | B16: GWh | C16: =C15*C11 -> 43.731522 | D16: =D15*D11 -> 45.017144 | E16: =E15*E11 -> 50.554353 | F16: =F15*F11 -> 43.050761 | G16: =G15*G11 -> 42.619605 | H16: =H15*H11 -> 43.296488 | I16: =I15*I11 -> 42.43294 | J16: =J15*J11 -> 42.218665 | ... N16: =N15*N11 -> 45.111472
A20: G_max HIDRO | B20: GWh | C20: 14.82 | D20: 14.84 | E20: 27.58 | F20: 18.15 | G20: 8.33 | H20: 6.01 | I20: 6.18 | J20: 7.81 | K20: 10.24 | L20: 13.91 | M20: 17.78 | N20: 19.7
A21: G_max BIOMASA | B21: GWh | C21: 0 | D21: 0 | E21: 0 | F21: 0.54 | G21: 5.92 | H21: 11.49 | I21: 10.67 | J21: 10.17 | K21: 8.07 | L21: 7.47 | M21: 4.82 | N21: 0.91
A22: G_max BIOGAS | B22: GWh | C22: 0.42 | D22: 0.4 | E22: 0.64 | F22: 1.03 | G22: 1.99 | H22: 2.05 | I22: 1.93 | J22: 1.99 | K22: 1.41 | L22: 0.69 | M22: 0.67 | N22: 0.62

Sheet Informe de respuestas 1
A1: Microsoft Excel 16.0 Informe de respuestas
A2: Hoja de cálculo: [TRABAJO DE CAMPO.xlsx]PL MULTIPERIODO
A3: Informe creado: 13/7/2026 22:14:57
A4: Resultado: Solver encontró una solución. Se cumplen todas las restricciones y condiciones óptimas.
A5: Motor de Solver
B6: Motor: Simplex LP
B7: Tiempo de la solución: 0,546 segundos.
B8: Iteraciones: 72 Subproblemas: 0
A9: Opciones de Solver
B10: Tiempo máximo Ilimitado, Iteraciones Ilimitado, Precision 0,000001, Usar escala automática
B11: Máximo de subproblemas Ilimitado, Máximo de soluciones de enteros Ilimitado, Tolerancia de enteros 1%, Asumir no negativo
A14: Celda objetivo (Mín)
B15: Celda | C15: Nombre | D15: Valor original | E15: Valor final
B16: $C$20 | C16: UDS Enero | D16: 2.4743801e+08 | E16: 2.4743801e+08
A19: Celdas de variables
B20: Celda | C20: Nombre | D20: Valor original | E20: Valor final | F20: Entero
B21: $C$7 | C21: GWh Enero | D21: 14.82 | E21: 14.82 | F21: Continuar
B22: $D$7 | C22: GWh Febrero | D22: 14.84 | E22: 14.84 | F22: Continuar
B23: $E$7 | C23: GWh Marzo | D23: 27.58 | E23: 27.58 | F23: Continuar
B24: $F$7 | C24: GWh Abril | D24: 18.15 | E24: 18.15 | F24: Continuar
B25: $G$7 | C25: GWh Mayo | D25: 8.33 | E25: 8.33 | F25: Continuar
B26: $H$7 | C26: GWh Junio | D26: 6.01 | E26: 6.01 | F26: Continuar
B27: $I$7 | C27: GWh Julio | D27: 6.18 | E27: 6.18 | F27: Continuar
B28: $J$7 | C28: GWh Agosto | D28: 7.81 | E28: 7.81 | F28: Continuar
B29: $K$7 | C29: GWh Septiembre | D29: 10.24 | E29: 10.24 | F29: Continuar
B30: $L$7 | C30: GWh Octubre | D30: 13.91 | E30: 13.91 | F30: Continuar
B31: $M$7 | C31: GWh Noviembre | D31: 17.78 | E31: 17.78 | F31: Continuar
B32: $N$7 | C32: GWh Diciembre | D32: 19.7 | E32: 19.7 | F32: Continuar
... B92: $N$12 | C92: GWh Diciembre | D92: 0 | E92: 0 | F92: Continuar
A95: Restricciones
B96: Celda | C96: Nombre | D96: Valor de la celda | E96: Fórmula | F96: Estado | G96: Demora
B97: $C$27 | C97: GWh Enero | D97: 313 | E97: $C$27=$C$29 | F97: Vinculante | G97: 0
B98: $D$27 | C98: GWh Febrero | D98: 281 | E98: $D$27=$D$29 | F98: Vinculante | G98: 0
B99: $E$27 | C99: GWh Marzo | D99: 275 | E99: $E$27=$E$29 | F99: Vinculante | G99: 0
B100: $F$27 | C100: GWh Abril | D100: 212 | E100: $F$27=$F$29 | F100: Vinculante | G100: 0
B101: $G$27 | C101: GWh Mayo | D101: 226 | E101: $G$27=$G$29 | F101: Vinculante | G101: 0
B102: $H$27 | C102: GWh Junio | D102: 243 | E102: $H$27=$H$29 | F102: Vinculante | G102: 0
B103: $I$27 | C103: GWh Julio | D103: 257 | E103: $I$27=$I$29 | F103: Vinculante | G103: 0
B104: $J$27 | C104: GWh Agosto | D104: 229 | E104: $J$27=$J$29 | F104: Vinculante | G104: 0
B105: $K$27 | C105: GWh Septiembre | D105: 218 | E105: $K$27=$K$29 | F105: Vinculante | G105: 0
...

Sheet Informe de sensibilidad 1
A1: Microsoft Excel 16.0 Informe de sensibilidad
A2: Hoja de cálculo: [TRABAJO DE CAMPO.xlsx]PL MULTIPERIODO
A3: Informe creado: 13/7/2026 22:15:00
A6: Celdas de variables
D7: Final | E7: Reducido | F7: Objetivo | G7: Permisible | H7: Permisible
B8: Celda | C8: Nombre | D8: Valor | E8: Coste | F8: Coeficiente | G8: Aumentar | H8: Reducir
B9: $C$7 | C9: GWh Enero | D9: 14.82 | E9: 0 | F9: 101930 | G9: 1e+30 | H9: 1e+30
B10: $D$7 | C10: GWh Febrero | D10: 14.84 | E10: 0 | F10: 101930 | G10: 1e+30 | H10: 1e+30
B11: $E$7 | C11: GWh Marzo | D11: 27.58 | E11: 0 | F11: 101930 | G11: 1e+30 | H11: 1e+30
B12: $F$7 | C12: GWh Abril | D12: 18.15 | E12: 0 | F12: 101930 | G12: 1e+30 | H12: 1e+30
B13: $G$7 | C13: GWh Mayo | D13: 8.33 | E13: 0 | F13: 101930 | G13: 1e+30 | H13: 1e+30
B14: $H$7 | C14: GWh Junio | D14: 6.01 | E14: 0 | F14: 101930 | G14: 1e+30 | H14: 1e+30
B15: $I$7 | C15: GWh Julio | D15: 6.18 | E15: 0 | F15: 101930 | G15: 1e+30 | H15: 1e+30
B16: $J$7 | C16: GWh Agosto | D16: 7.81 | E16: 0 | F16: 101930 | G16: 1e+30 | H16: 1e+30
B17: $K$7 | C17: GWh Septiembre | D17: 10.24 | E17: 0 | F17: 101930 | G17: 1e+30 | H17: 1e+30
B18: $L$7 | C18: GWh Octubre | D18: 13.91 | E18: 0 | F18: 101930 | G18: 1e+30 | H18: 1e+30
B19: $M$7 | C19: GWh Noviembre | D19: 17.78 | E19: 0 | F19: 101930 | G19: 1e+30 | H19: 1e+30
B20: $N$7 | C20: GWh Diciembre | D20: 19.7 | E20: 0 | F20: 101930 | G20: 1e+30 | H20: 1e+30
... B80: $N$12 | C80: GWh Diciembre | D80: 0 | E80: 1441316.1 | F80: 1500000 | G80: 1e+30 | H80: 1441316.1
A82: Restricciones
D83: Final | E83: Sombra | F83: Restricción | G83: Permisible | H83: Permisible
B84: Celda | C84: Nombre | D84: Valor | E84: Precio | F84: Lado derecho | G84: Aumentar | H84: Reducir
B85: $C$27 | C85: GWh Enero | D85: 313 | E85: 74507.772 | F85: 313 | G85: 462.0494 | H85: 298.2934
B86: $D$27 | C86: GWh Febrero | D86: 281 | E86: 73295.337 | F86: 281 | G86: 494.0494 | H86: 266.2934
B87: $E$27 | C87: GWh Marzo | D87: 275 | E87: 73284.974 | F87: 275 | G87: 500.0494 | H87: 247.7677
B88: $F$27 | C88: GWh Abril | D88: 212 | E88: 73025.907 | F88: 212 | G88: 563.0494 | H88: 192.9702
B89: $G$27 | C89: GWh Mayo | D89: 226 | E89: 88756.477 | F89: 226 | G89: 549.0494 | H89: 210.3284
B90: $H$27 | C90: GWh Junio | D90: 243 | E90: 100590.67 | F90: 243 | G90: 532.0494 | H90: 224.13425
B91: $I$27 | C91: GWh Julio | D91: 257 | E91: 97191.71 | F91: 257 | G91: 518.0494 | H91: 238.8773
B92: $J$27 | C92: GWh Agosto | D92: 229 | E92: 85316.062 | F92: 229 | G92: 546.0494 | H92: 209.72895
B93: $K$27 | C93: GWh Septiembre | D93: 218 | E93: 79077.72 | F93: 218 | G93: 557.0494 | H93: 198.9702
B94: $L$27 | C94: GWh Octubre | D94: 248 | E94: 68051.813 | F94: 248 | G94: 527.0494 | H94: 226.70245
B95: $M$27 | C95: GWh Noviembre | D95: 271 | E95: 63906.736 | F95: 271 | G95: 504.0494 | H95: 248.54445
B96: $N$27 | C96: GWh Diciembre | D96: 307 | E96: 58683.938 | F96: 307 | G96: 468.0494 | H96: 286.51305
... B156: $N$63 | C156: GWh Diciembre | D156: 318.13472 | E156: 0 | F156: 803.16 | G156: 1e+30 | H156: 485.02528

Sheet PL MULTIPERIODO
A2: PROGRAMACIÓN LINEAL MULTIPERIODO- TUCUMÁN 2027
A5: Variables de decision
A6: Variable | B6: Unidad | C6: Enero | D6: Febrero | E6: Marzo | F6: Abril | G6: Mayo | H6: Junio | I6: Julio | J6: Agosto | K6: Septiembre | L6: Octubre | M6: Noviembre | N6: Diciembre
A7: X_HIDRO (hidro <=50MW) | B7: GWh | C7: 14.82 | D7: 14.84 | E7: 27.58 | F7: 18.15 | G7: 8.33 | H7: 6.01 | I7: 6.18 | J7: 7.81 | K7: 10.24 | L7: 13.91 | M7: 17.78 | N7: 19.7
A8: X_BIOMASA (renov. biomasa) | B8: GWh | C8: 0 | D8: 0 | E8: 0 | F8: 0.54 | G8: 5.92 | H8: 11.49 | I8: 10.67 | J8: 10.17 | K8: 8.07 | L8: 7.47 | M8: 4.82 | N8: 0.91
A9: X_BIOGAS (renov. biogás) | B9: GWh | C9: 0.42 | D9: 0.4 | E9: 0.64 | F9: 1.03 | G9: 1.99 | H9: 2.05 | I9: 1.93 | J9: 1.99 | K9: 1.41 | L9: 0.69 | M9: 0.67 | N9: 0.62
A10: Y (energía convencional MEM) | B10: GWh | C10: 309.11233 | D10: 275.95171 | E10: 256.75409 | F10: 199.96912 | G10: 217.95689 | H10: 232.26347 | I10: 247.54124 | J10: 217.3357 | K10: 206.18674 | L10: 234.92482 | M10: 257.55902 | N10: 296.90472
A11: R (reserva térmica contratada) | B11: GWh | C11: 43.731522 | D11: 45.017144 | E11: 50.554353 | F11: 43.050761 | G11: 42.619605 | H11: 43.296488 | I11: 42.43294 | J11: 42.218665 | K11: 42.191476 | L11: 42.758041 | M11: 44.175761 | N11: 45.111472
A12: ENS (Energía No Suministrada) | B12: GWh | C12: 0 | D12: 0 | E12: 0 | F12: 0 | G12: 0 | H12: 0 | I12: 0 | J12: 0 | K12: 0 | L12: 0 | M12: 0 | N12: 0
A16: Función Objetivo
A17: Parámetro | B17: Unidad | C17: Enero | D17: Febrero | E17: Marzo | F17: Abril | G17: Mayo | H17: Junio | I17: Julio | J17: Agosto | K17: Septiembre | L17: Octubre | M17: Noviembre | N17: Diciembre
A18: Costo Mensual total | B18: UDS | C18: =$B$72*C7+$B$73*C8+$B$74*C9+C78*C10+$B$75*C11+$B$76*C12 -> 23863474 | D18: =$B$72*D7+$B$73*D8+$B$74*D9+D78*D10+$B$75*D11+$B$76*D12 -> 21156997 | E18: =$B$72*E7+$B$73*E8+$B$74*E9+E78*E10+$B$75*E11+$B$76*E12 -> 21141122 | F18: =$B$72*F7+$B$73*F8+$B$74*F9+F78*F10+$B$75*F11+$B$76*F12 -> 16233008 | G18: =$B$72*G7+$B$73*G8+$B$74*G9+G78*G10+$B$75*G11+$B$76*G12 -> 20629795 | H18: =$B$72*H7+$B$73*H8+$B$74*H9+H78*H10+$B$75*H11+$B$76*H12 -> 24974371 | I18: =$B$72*I7+$B$73*I8+$B$74*I9+I78*I10+$B$75*I11+$B$76*I12 -> 25540464 | J18: =$B$72*J7+$B$73*J8+$B$74*J9+J78*J10+$B$75*J11+$B$76*J12 -> 20330047 | ... N18: =$B$72*N7+$B$73*N8+$B$74*N9+N78*N10+$B$75*N11+$B$76*N12 -> 19096407
A20: Costo total anual | B20: UDS | C20: =SUM(C18:N18) -> 2.4743801e+08
A23: Restricciones
A25: Balance de energía
B26: Unidad | C26: Enero | D26: Febrero | E26: Marzo | F26: Abril | G26: Mayo | H26: Junio | I26: Julio | J26: Agosto | K26: Septiembre | L26: Octubre | M26: Noviembre | N26: Diciembre
A27: LHS | B27: GWh | C27: =(1-$B$83)*(C7+C8+C9+C10)+C12 -> 313 | D27: =(1-$B$83)*(D7+D8+D9+D10)+D12 -> 281 | E27: =(1-$B$83)*(E7+E8+E9+E10)+E12 -> 275 | F27: =(1-$B$83)*(F7+F8+F9+F10)+F12 -> 212 | G27: =(1-$B$83)*(G7+G8+G9+G10)+G12 -> 226 | H27: =(1-$B$83)*(H7+H8+H9+H10)+H12 -> 243 | I27: =(1-$B$83)*(I7+I8+I9+I10)+I12 -> 257 | J27: =(1-$B$83)*(J7+J8+J9+J10)+J12 -> 229 | ... N27: =(1-$B$83)*(N7+N8+N9+N10)+N12 -> 307
A28: SIGNO | C28: = | D28: = | E28: = | F28: = | G28: = | H28: = | I28: = | J28: = | K28: = | L28: = | M28: = | N28: =
A29: RHS= D_t | B29: GWh | C29: 313 | D29: 281 | E29: 275 | F29: 212 | G29: 226 | H29: 243 | I29: 257 | J29: 229 | K29: 218 | L29: 248 | M29: 271 | N29: 307
A31: Stock de seguridad
B32: Unidad | C32: Enero | D32: Febrero | E32: Marzo | F32: Abril | G32: Mayo | H32: Junio | I32: Julio | J32: Agosto | K32: Septiembre | L32: Octubre | M32: Noviembre | N32: Diciembre
A33: LHS=R_t | B33: GWh | C33: =C11 -> 43.731522 | D33: =D11 -> 45.017144 | E33: =E11 -> 50.554353 | F33: =F11 -> 43.050761 | G33: =G11 -> 42.619605 | H33: =H11 -> 43.296488 | I33: =I11 -> 42.43294 | J33: =J11 -> 42.218665 | ... N33: =N11 -> 45.111472
A34: SIGNO | C34: >= | D34: >= | E34: >= | F34: >= | G34: >= | H34: >= | I34: >= | J34: >= | K34: >= | L34: >= | M34: >= | N34: >=
A35: RHS= SS_t | B35: GWh | C35: =DATOSMENSUALES!C16 -> 43.731522 | D35: =DATOSMENSUALES!D16 -> 45.017144 | E35: =DATOSMENSUALES!E16 -> 50.554353 | F35: =DATOSMENSUALES!F16 -> 43.050761 | G35: =DATOSMENSUALES!G16 -> 42.619605 | H35: =DATOSMENSUALES!H16 -> 43.296488 | I35: =DATOSMENSUALES!I16 -> 42.43294 | J35: =DATOSMENSUALES!J16 -> 42.218665 | ... N35: =DATOSMENSUALES!N16 -> 45.111472
A36: Holgura | B36: GWh
A39: Capacidad física de generación renovable
A41: HIDRO | B41: Unidad | C41: Enero | D41: Febrero | E41: Marzo | F41: Abril | G41: Mayo | H41: Junio | I41: Julio | J41: Agosto | K41: Septiembre | L41: Octubre | M41: Noviembre | N41: Diciembre
A42: LHS | B42: GWh | C42: =C7 -> 14.82 | D42: =D7 -> 14.84 | E42: =E7 -> 27.58 | F42: =F7 -> 18.15 | G42: =G7 -> 8.33 | H42: =H7 -> 6.01 | I42: =I7 -> 6.18 | J42: =J7 -> 7.81 | ... N42: =N7 -> 19.7
A43: SIGNO | C43: = | D43: = | E43: = | F43: = | G43: = | H43: = | I43: = | J43: = | K43: = | L43: = | M43: = | N43: =
A44: RHS (máximo)= Gmax | B44: GWh | C44: 14.82 | D44: 14.84 | E44: 27.58 | F44: 18.15 | G44: 8.33 | H44: 6.01 | I44: 6.18 | J44: 7.81 | K44: 10.24 | L44: 13.91 | M44: 17.78 | N44: 19.7
A48: BIOMASA | B48: Unidad | C48: Enero | D48: Febrero | E48: Marzo | F48: Abril | G48: Mayo | H48: Junio | I48: Julio | J48: Agosto | K48: Septiembre | L48: Octubre | M48: Noviembre | N48: Diciembre
A49: LHS | B49: GWh | C49: =C8 -> 0 | D49: =D8 -> 0 | E49: =E8 -> 0 | F49: =F8 -> 0.54 | G49: =G8 -> 5.92 | H49: =H8 -> 11.49 | I49: =I8 -> 10.67 | J49: =J8 -> 10.17 | ... N49: =N8 -> 0.91
A50: SIGNO | C50: = | D50: = | E50: = | F50: = | G50: = | H50: = | I50: = | J50: = | K50: = | L50: = | M50: = | N50: =
A51: RHS | B51: GWh | C51: 0 | D51: 0 | E51: 0 | F51: 0.54 | G51: 5.92 | H51: 11.49 | I51: 10.67 | J51: 10.17 | K51: 8.07 | L51: 7.47 | M51: 4.82 | N51: 0.91
A54: BIOGAS | B54: Unidad | C54: Enero | D54: Febrero | E54: Marzo | F54: Abril | G54: Mayo | H54: Junio | I54: Julio | J54: Agosto | K54: Septiembre | L54: Octubre | M54: Noviembre | N54: Diciembre
A55: LHS | B55: GWh | C55: =C9 -> 0.42 | D55: =D9 -> 0.4 | E55: =E9 -> 0.64 | F55: =F9 -> 1.03 | G55: =G9 -> 1.99 | H55: =H9 -> 2.05 | I55: =I9 -> 1.93 | J55: =J9 -> 1.99 | ... N55: =N9 -> 0.62
A56: SIGNO | C56: = | D56: = | E56: = | F56: = | G56: = | H56: = | I56: = | J56: = | K56: = | L56: = | M56: = | N56: =
A57: RHS | B57: GWh | C57: 0.42 | D57: 0.4 | E57: 0.64 | F57: 1.03 | G57: 1.99 | H57: 2.05 | I57: 1.93 | J57: 1.99 | K57: 1.41 | L57: 0.69 | M57: 0.67 | N57: 0.62
A61: Capacidad máxima de transporte
B62: Unidad | C62: Enero | D62: Febrero | E62: Marzo | F62: Abril | G62: Mayo | H62: Junio | I62: Julio | J62: Agosto | K62: Septiembre | L62: Octubre | M62: Noviembre | N62: Diciembre
...

Sheet Informe de sensibilidad 2
A1: Microsoft Excel 16.0 Informe de sensibilidad
A2: Hoja de cálculo: [TRABAJO DE CAMPO.xlsx]PL MUlTIPERIODO A. SENSIBILIDAD
A3: Informe creado: 13/7/2026 22:27:58
A6: Celdas de variables
D7: Final | E7: Reducido | F7: Objetivo | G7: Permisible | H7: Permisible
B8: Celda | C8: Nombre | D8: Valor | E8: Coste | F8: Coeficiente | G8: Aumentar | H8: Reducir
B9: $C$7 | C9: GWh Enero | D9: 14.82 | E9: 0 | F9: 101930 | G9: 1e+30 | H9: 1e+30
B10: $D$7 | C10: GWh Febrero | D10: 14.84 | E10: 0 | F10: 101930 | G10: 1e+30 | H10: 1e+30
B11: $E$7 | C11: GWh Marzo | D11: 27.58 | E11: 0 | F11: 101930 | G11: 1e+30 | H11: 1e+30
B12: $F$7 | C12: GWh Abril | D12: 18.15 | E12: 0 | F12: 101930 | G12: 1e+30 | H12: 1e+30
B13: $G$7 | C13: GWh Mayo | D13: 8.33 | E13: 0 | F13: 101930 | G13: 1e+30 | H13: 1e+30
B14: $H$7 | C14: GWh Junio | D14: 6.01 | E14: 0 | F14: 101930 | G14: 1e+30 | H14: 1e+30
B15: $I$7 | C15: GWh Julio | D15: 6.18 | E15: 0 | F15: 101930 | G15: 1e+30 | H15: 1e+30
B16: $J$7 | C16: GWh Agosto | D16: 7.81 | E16: 0 | F16: 101930 | G16: 1e+30 | H16: 1e+30
B17: $K$7 | C17: GWh Septiembre | D17: 10.24 | E17: 0 | F17: 101930 | G17: 1e+30 | H17: 1e+30
B18: $L$7 | C18: GWh Octubre | D18: 13.91 | E18: 0 | F18: 101930 | G18: 1e+30 | H18: 1e+30
B19: $M$7 | C19: GWh Noviembre | D19: 17.78 | E19: 0 | F19: 101930 | G19: 1e+30 | H19: 1e+30
B20: $N$7 | C20: GWh Diciembre | D20: 19.7 | E20: 0 | F20: 101930 | G20: 1e+30 | H20: 1e+30
... B80: $N$12 | C80: GWh Diciembre | D80: 0 | E80: 1441316.1 | F80: 1500000 | G80: 1e+30 | H80: 1441316.1
A82: Restricciones
D83: Final | E83: Sombra | F83: Restricción | G83: Permisible | H83: Permisible
B84: Celda | C84: Nombre | D84: Valor | E84: Precio | F84: Lado derecho | G84: Aumentar | H84: Reducir
B85: $C$27 | C85: GWh Enero | D85: 374 | E85: 74507.772 | F85: 374 | G85: 401.0494 | H85: 359.2934
B86: $D$27 | C86: GWh Febrero | D86: 335 | E86: 73295.337 | F86: 335 | G86: 440.0494 | H86: 320.2934
B87: $E$27 | C87: GWh Marzo | D87: 315 | E87: 73284.974 | F87: 315 | G87: 460.0494 | H87: 287.7677
B88: $F$27 | C88: GWh Abril | D88: 224 | E88: 73025.907 | F88: 224 | G88: 551.0494 | H88: 204.9702
B89: $G$27 | C89: GWh Mayo | D89: 226 | E89: 88756.477 | F89: 226 | G89: 549.0494 | H89: 210.3284
B90: $H$27 | C90: GWh Junio | D90: 243 | E90: 100590.67 | F90: 243 | G90: 532.0494 | H90: 224.13425
B91: $I$27 | C91: GWh Julio | D91: 257 | E91: 97191.71 | F91: 257 | G91: 518.0494 | H91: 238.8773
B92: $J$27 | C92: GWh Agosto | D92: 229 | E92: 85316.062 | F92: 229 | G92: 546.0494 | H92: 209.72895
B93: $K$27 | C93: GWh Septiembre | D93: 218 | E93: 79077.72 | F93: 218 | G93: 557.0494 | H93: 198.9702
B94: $L$27 | C94: GWh Octubre | D94: 248 | E94: 68051.813 | F94: 248 | G94: 527.0494 | H94: 226.70245
B95: $M$27 | C95: GWh Noviembre | D95: 271 | E95: 63906.736 | F95: 271 | G95: 504.0494 | H95: 248.54445
B96: $N$27 | C96: GWh Diciembre | D96: 353 | E96: 58683.938 | F96: 353 | G96: 422.0494 | H96: 332.51305
... B156: $N$63 | C156: GWh Diciembre | D156: 365.80311 | E156: 0 | F156: 803.16 | G156: 1e+30 | H156: 437.35689

Sheet Informe de respuestas 2
A1: Microsoft Excel 16.0 Informe de respuestas
A2: Hoja de cálculo: [TRABAJO DE CAMPO.xlsx]PL MUlTIPERIODO A. SENSIBILIDAD
A3: Informe creado: 13/7/2026 22:27:55
A4: Resultado: Solver encontró una solución. Se cumplen todas las restricciones y condiciones óptimas.
A5: Motor de Solver
B6: Motor: Simplex LP
B7: Tiempo de la solución: 0,547 segundos.
B8: Iteraciones: 72 Subproblemas: 0
A9: Opciones de Solver
B10: Tiempo máximo Ilimitado, Iteraciones Ilimitado, Precision 0,000001, Usar escala automática
B11: Máximo de subproblemas Ilimitado, Máximo de soluciones de enteros Ilimitado, Tolerancia de enteros 1%, Asumir no negativo
A14: Celda objetivo (Mín)
B15: Celda | C15: Nombre | D15: Valor original | E15: Valor final
B16: $C$20 | C16: UDS Enero | D16: 2.624481e+08 | E16: 2.624481e+08
A19: Celdas de variables
B20: Celda | C20: Nombre | D20: Valor original | E20: Valor final | F20: Entero
B21: $C$7 | C21: GWh Enero | D21: 14.82 | E21: 14.82 | F21: Continuar
B22: $D$7 | C22: GWh Febrero | D22: 14.84 | E22: 14.84 | F22: Continuar
B23: $E$7 | C23: GWh Marzo | D23: 27.58 | E23: 27.58 | F23: Continuar
B24: $F$7 | C24: GWh Abril | D24: 18.15 | E24: 18.15 | F24: Continuar
B25: $G$7 | C25: GWh Mayo | D25: 8.33 | E25: 8.33 | F25: Continuar
B26: $H$7 | C26: GWh Junio | D26: 6.01 | E26: 6.01 | F26: Continuar
B27: $I$7 | C27: GWh Julio | D27: 6.18 | E27: 6.18 | F27: Continuar
B28: $J$7 | C28: GWh Agosto | D28: 7.81 | E28: 7.81 | F28: Continuar
B29: $K$7 | C29: GWh Septiembre | D29: 10.24 | E29: 10.24 | F29: Continuar
B30: $L$7 | C30: GWh Octubre | D30: 13.91 | E30: 13.91 | F30: Continuar
B31: $M$7 | C31: GWh Noviembre | D31: 17.78 | E31: 17.78 | F31: Continuar
B32: $N$7 | C32: GWh Diciembre | D32: 19.7 | E32: 19.7 | F32: Continuar
... B92: $N$12 | C92: GWh Diciembre | D92: 0 | E92: 0 | F92: Continuar
A95: Restricciones
B96: Celda | C96: Nombre | D96: Valor de la celda | E96: Fórmula | F96: Estado | G96: Demora
B97: $C$27 | C97: GWh Enero | D97: 374 | E97: $C$27=$C$29 | F97: Vinculante | G97: 0
B98: $D$27 | C98: GWh Febrero | D98: 335 | E98: $D$27=$D$29 | F98: Vinculante | G98: 0
B99: $E$27 | C99: GWh Marzo | D99: 315 | E99: $E$27=$E$29 | F99: Vinculante | G99: 0
B100: $F$27 | C100: GWh Abril | D100: 224 | E100: $F$27=$F$29 | F100: Vinculante | G100: 0
B101: $G$27 | C101: GWh Mayo | D101: 226 | E101: $G$27=$G$29 | F101: Vinculante | G101: 0
B102: $H$27 | C102: GWh Junio | D102: 243 | E102: $H$27=$H$29 | F102: Vinculante | G102: 0
B103: $I$27 | C103: GWh Julio | D103: 257 | E103: $I$27=$I$29 | F103: Vinculante | G103: 0
B104: $J$27 | C104: GWh Agosto | D104: 229 | E104: $J$27=$J$29 | F104: Vinculante | G104: 0
B105: $K$27 | C105: GWh Septiembre | D105: 218 | E105: $K$27=$K$29 | F105: Vinculante | G105: 0
...

Sheet PL MULT. AS-TEMPERATURA +10%
A2: PROGRAMACIÓN LINEAL MULTIPERIODO- ANALISIS DE SENSIBILIDAD
A5: Variables de decision
A6: Variable | B6: Unidad | C6: Enero | D6: Febrero | E6: Marzo | F6: Abril | G6: Mayo | H6: Junio | I6: Julio | J6: Agosto | K6: Septiembre | L6: Octubre | M6: Noviembre | N6: Diciembre
A7: X_HIDRO (hidro <=50MW) | B7: GWh | C7: 14.82 | D7: 14.84 | E7: 27.58 | F7: 18.15 | G7: 8.33 | H7: 6.01 | I7: 6.18 | J7: 7.81 | K7: 10.24 | L7: 13.91 | M7: 17.78 | N7: 19.7
A8: X_BIOMASA (renov. biomasa) | B8: GWh | C8: 0 | D8: 0 | E8: 0 | F8: 0.54 | G8: 5.92 | H8: 11.49 | I8: 10.67 | J8: 10.17 | K8: 8.07 | L8: 7.47 | M8: 4.82 | N8: 0.91
A9: X_BIOGAS (renov. biogás) | B9: GWh | C9: 0.42 | D9: 0.4 | E9: 0.64 | F9: 1.03 | G9: 1.99 | H9: 2.05 | I9: 1.93 | J9: 1.99 | K9: 1.41 | L9: 0.69 | M9: 0.67 | N9: 0.62
A10: Y (energía convencional MEM) | B10: GWh | C10: 372.32477 | D10: 331.91026 | E10: 298.20487 | F10: 212.40435 | G10: 217.95689 | H10: 232.26347 | I10: 247.54124 | J10: 217.3357 | K10: 206.18674 | L10: 234.92482 | M10: 257.55902 | N10: 344.57311
A11: R (reserva térmica contratada) | B11: GWh | C11: 43.731522 | D11: 45.017144 | E11: 50.554353 | F11: 43.050761 | G11: 42.619605 | H11: 43.296488 | I11: 42.43294 | J11: 42.218665 | K11: 42.191476 | L11: 42.758041 | M11: 44.175761 | N11: 45.111472
A12: ENS (Energía No Suministrada) | B12: GWh | C12: 0 | D12: 0 | E12: 0 | F12: 0 | G12: 0 | H12: 0 | I12: 0 | J12: 0 | K12: 0 | L12: 0 | M12: 0 | N12: 0
A16: Función Objetivo
A17: Parámetro | B17: Unidad | C17: Enero | D17: Febrero | E17: Marzo | F17: Abril | G17: Mayo | H17: Junio | I17: Julio | J17: Agosto | K17: Septiembre | L17: Octubre | M17: Noviembre | N17: Diciembre
A18: Costo Mensual total | B18: UDS | C18: =$B$72*C7+$B$73*C8+$B$74*C9+C78*C10+$B$75*C11+$B$76*C12 -> 28408448 | D18: =$B$72*D7+$B$73*D8+$B$74*D9+D78*D10+$B$75*D11+$B$76*D12 -> 25114946 | E18: =$B$72*E7+$B$73*E8+$B$74*E9+E78*E10+$B$75*E11+$B$76*E12 -> 24072521 | F18: =$B$72*F7+$B$73*F8+$B$74*F9+F78*F10+$B$75*F11+$B$76*F12 -> 17109319 | G18: =$B$72*G7+$B$73*G8+$B$74*G9+G78*G10+$B$75*G11+$B$76*G12 -> 20629795 | H18: =$B$72*H7+$B$73*H8+$B$74*H9+H78*H10+$B$75*H11+$B$76*H12 -> 24974371 | I18: =$B$72*I7+$B$73*I8+$B$74*I9+I78*I10+$B$75*I11+$B$76*I12 -> 25540464 | J18: =$B$72*J7+$B$73*J8+$B$74*J9+J78*J10+$B$75*J11+$B$76*J12 -> 20330047 | ... N18: =$B$72*N7+$B$73*N8+$B$74*N9+N78*N10+$B$75*N11+$B$76*N12 -> 21795868
A20: Costo total anual | B20: UDS | C20: =SUM(C18:N18) -> 2.624481e+08
A23: Restricciones
A25: Balance de energía
B26: Unidad | C26: Enero | D26: Febrero | E26: Marzo | F26: Abril | G26: Mayo | H26: Junio | I26: Julio | J26: Agosto | K26: Septiembre | L26: Octubre | M26: Noviembre | N26: Diciembre
A27: LHS | B27: GWh | C27: =(1-$B$83)*(C7+C8+C9+C10)+C12 -> 374 | D27: =(1-$B$83)*(D7+D8+D9+D10)+D12 -> 335 | E27: =(1-$B$83)*(E7+E8+E9+E10)+E12 -> 315 | F27: =(1-$B$83)*(F7+F8+F9+F10)+F12 -> 224 | G27: =(1-$B$83)*(G7+G8+G9+G10)+G12 -> 226 | H27: =(1-$B$83)*(H7+H8+H9+H10)+H12 -> 243 | I27: =(1-$B$83)*(I7+I8+I9+I10)+I12 -> 257 | J27: =(1-$B$83)*(J7+J8+J9+J10)+J12 -> 229 | ... N27: =(1-$B$83)*(N7+N8+N9+N10)+N12 -> 353
A28: SIGNO | C28: = | D28: = | E28: = | F28: = | G28: = | H28: = | I28: = | J28: = | K28: = | L28: = | M28: = | N28: =
A29: RHS= D_t | B29: GWh | C29: 374 | D29: 335 | E29: 315 | F29: 224 | G29: 226 | H29: 243 | I29: 257 | J29: 229 | K29: 218 | L29: 248 | M29: 271 | N29: 353
A31: Stock de seguridad
B32: Unidad | C32: Enero | D32: Febrero | E32: Marzo | F32: Abril | G32: Mayo | H32: Junio | I32: Julio | J32: Agosto | K32: Septiembre | L32: Octubre | M32: Noviembre | N32: Diciembre
A33: LHS=R_t | B33: GWh | C33: =C11 -> 43.731522 | D33: =D11 -> 45.017144 | E33: =E11 -> 50.554353 | F33: =F11 -> 43.050761 | G33: =G11 -> 42.619605 | H33: =H11 -> 43.296488 | I33: =I11 -> 42.43294 | J33: =J11 -> 42.218665 | ... N33: =N11 -> 45.111472
A34: SIGNO | C34: >= | D34: >= | E34: >= | F34: >= | G34: >= | H34: >= | I34: >= | J34: >= | K34: >= | L34: >= | M34: >= | N34: >=
A35: RHS= SS_t | B35: GWh | C35: =DATOSMENSUALES!C16 -> 43.731522 | D35: =DATOSMENSUALES!D16 -> 45.017144 | E35: =DATOSMENSUALES!E16 -> 50.554353 | F35: =DATOSMENSUALES!F16 -> 43.050761 | G35: =DATOSMENSUALES!G16 -> 42.619605 | H35: =DATOSMENSUALES!H16 -> 43.296488 | I35: =DATOSMENSUALES!I16 -> 42.43294 | J35: =DATOSMENSUALES!J16 -> 42.218665 | ... N35: =DATOSMENSUALES!N16 -> 45.111472
A36: Holgura | B36: GWh
A39: Capacidad física de generación renovable
A41: HIDRO | B41: Unidad | C41: Enero | D41: Febrero | E41: Marzo | F41: Abril | G41: Mayo | H41: Junio | I41: Julio | J41: Agosto | K41: Septiembre | L41: Octubre | M41: Noviembre | N41: Diciembre
A42: LHS | B42: GWh | C42: =C7 -> 14.82 | D42: =D7 -> 14.84 | E42: =E7 -> 27.58 | F42: =F7 -> 18.15 | G42: =G7 -> 8.33 | H42: =H7 -> 6.01 | I42: =I7 -> 6.18 | J42: =J7 -> 7.81 | ... N42: =N7 -> 19.7
A43: SIGNO | C43: = | D43: = | E43: = | F43: = | G43: = | H43: = | I43: = | J43: = | K43: = | L43: = | M43: = | N43: =
A44: RHS (máximo)= Gmax | B44: GWh | C44: 14.82 | D44: 14.84 | E44: 27.58 | F44: 18.15 | G44: 8.33 | H44: 6.01 | I44: 6.18 | J44: 7.81 | K44: 10.24 | L44: 13.91 | M44: 17.78 | N44: 19.7
A48: BIOMASA | B48: Unidad | C48: Enero | D48: Febrero | E48: Marzo | F48: Abril | G48: Mayo | H48: Junio | I48: Julio | J48: Agosto | K48: Septiembre | L48: Octubre | M48: Noviembre | N48: Diciembre
A49: LHS | B49: GWh | C49: =C8 -> 0 | D49: =D8 -> 0 | E49: =E8 -> 0 | F49: =F8 -> 0.54 | G49: =G8 -> 5.92 | H49: =H8 -> 11.49 | I49: =I8 -> 10.67 | J49: =J8 -> 10.17 | ... N49: =N8 -> 0.91
A50: SIGNO | C50: = | D50: = | E50: = | F50: = | G50: = | H50: = | I50: = | J50: = | K50: = | L50: = | M50: = | N50: =
A51: RHS | B51: GWh | C51: 0 | D51: 0 | E51: 0 | F51: 0.54 | G51: 5.92 | H51: 11.49 | I51: 10.67 | J51: 10.17 | K51: 8.07 | L51: 7.47 | M51: 4.82 | N51: 0.91
A54: BIOGAS | B54: Unidad | C54: Enero | D54: Febrero | E54: Marzo | F54: Abril | G54: Mayo | H54: Junio | I54: Julio | J54: Agosto | K54: Septiembre | L54: Octubre | M54: Noviembre | N54: Diciembre
A55: LHS | B55: GWh | C55: =C9 -> 0.42 | D55: =D9 -> 0.4 | E55: =E9 -> 0.64 | F55: =F9 -> 1.03 | G55: =G9 -> 1.99 | H55: =H9 -> 2.05 | I55: =I9 -> 1.93 | J55: =J9 -> 1.99 | ... N55: =N9 -> 0.62
A56: SIGNO | C56: = | D56: = | E56: = | F56: = | G56: = | H56: = | I56: = | J56: = | K56: = | L56: = | M56: = | N56: =
A57: RHS | B57: GWh | C57: 0.42 | D57: 0.4 | E57: 0.64 | F57: 1.03 | G57: 1.99 | H57: 2.05 | I57: 1.93 | J57: 1.99 | K57: 1.41 | L57: 0.69 | M57: 0.67 | N57: 0.62
A61: Capacidad máxima de transporte
B62: Unidad | C62: Enero | D62: Febrero | E62: Marzo | F62: Abril | G62: Mayo | H62: Junio | I62: Julio | J62: Agosto | K62: Septiembre | L62: Octubre | M62: Noviembre | N62: Diciembre
...

Sheet Informe de sensibilidad 3
A1: Microsoft Excel 16.0 Informe de sensibilidad
A2: Hoja de cálculo: [TRABAJO DE CAMPO.xlsx]PL MULT. AS-TMAX
A3: Informe creado: 13/7/2026 23:12:59
A6: Celdas de variables
D7: Final | E7: Reducido | F7: Objetivo | G7: Permisible | H7: Permisible
B8: Celda | C8: Nombre | D8: Valor | E8: Coste | F8: Coeficiente | G8: Aumentar | H8: Reducir
B9: $C$7 | C9: GWh Enero | D9: 14.82 | E9: 0 | F9: 101930 | G9: 1e+30 | H9: 1e+30
B10: $D$7 | C10: GWh Febrero | D10: 14.84 | E10: 0 | F10: 101930 | G10: 1e+30 | H10: 1e+30
B11: $E$7 | C11: GWh Marzo | D11: 27.58 | E11: 0 | F11: 101930 | G11: 1e+30 | H11: 1e+30
B12: $F$7 | C12: GWh Abril | D12: 18.15 | E12: 0 | F12: 101930 | G12: 1e+30 | H12: 1e+30
B13: $G$7 | C13: GWh Mayo | D13: 8.33 | E13: 0 | F13: 101930 | G13: 1e+30 | H13: 1e+30
B14: $H$7 | C14: GWh Junio | D14: 6.01 | E14: 0 | F14: 101930 | G14: 1e+30 | H14: 1e+30
B15: $I$7 | C15: GWh Julio | D15: 6.18 | E15: 0 | F15: 101930 | G15: 1e+30 | H15: 1e+30
B16: $J$7 | C16: GWh Agosto | D16: 7.81 | E16: 0 | F16: 101930 | G16: 1e+30 | H16: 1e+30
B17: $K$7 | C17: GWh Septiembre | D17: 10.24 | E17: 0 | F17: 101930 | G17: 1e+30 | H17: 1e+30
B18: $L$7 | C18: GWh Octubre | D18: 13.91 | E18: 0 | F18: 101930 | G18: 1e+30 | H18: 1e+30
B19: $M$7 | C19: GWh Noviembre | D19: 17.78 | E19: 0 | F19: 101930 | G19: 1e+30 | H19: 1e+30
B20: $N$7 | C20: GWh Diciembre | D20: 19.7 | E20: 0 | F20: 101930 | G20: 1e+30 | H20: 1e+30
... B80: $N$12 | C80: GWh Diciembre | D80: 17.5 | E80: 0 | F80: 1500000 | G80: 1e+30 | H80: 1441316.1
A82: Restricciones
D83: Final | E83: Sombra | F83: Restricción | G83: Permisible | H83: Permisible
B84: Celda | C84: Nombre | D84: Valor | E84: Precio | F84: Lado derecho | G84: Aumentar | H84: Reducir
B85: $C$27 | C85: GWh Enero | D85: 313 | E85: 1500000 | F85: 313 | G85: 1e+30 | H85: 23.5
B86: $D$27 | C86: GWh Febrero | D86: 281 | E86: 73295.337 | F86: 281 | G86: 8.5 | H86: 266.2934
B87: $E$27 | C87: GWh Marzo | D87: 275 | E87: 73284.974 | F87: 275 | G87: 14.5 | H87: 247.7677
B88: $F$27 | C88: GWh Abril | D88: 212 | E88: 73025.907 | F88: 212 | G88: 77.5 | H88: 192.9702
B89: $G$27 | C89: GWh Mayo | D89: 226 | E89: 88756.477 | F89: 226 | G89: 63.5 | H89: 210.3284
B90: $H$27 | C90: GWh Junio | D90: 243 | E90: 100590.67 | F90: 243 | G90: 46.5 | H90: 224.13425
B91: $I$27 | C91: GWh Julio | D91: 257 | E91: 97191.71 | F91: 257 | G91: 32.5 | H91: 238.8773
B92: $J$27 | C92: GWh Agosto | D92: 229 | E92: 85316.062 | F92: 229 | G92: 60.5 | H92: 209.72895
B93: $K$27 | C93: GWh Septiembre | D93: 218 | E93: 79077.72 | F93: 218 | G93: 71.5 | H93: 198.9702
B94: $L$27 | C94: GWh Octubre | D94: 248 | E94: 68051.813 | F94: 248 | G94: 41.5 | H94: 226.70245
B95: $M$27 | C95: GWh Noviembre | D95: 271 | E95: 63906.736 | F95: 271 | G95: 18.5 | H95: 248.54445
B96: $N$27 | C96: GWh Diciembre | D96: 307 | E96: 1500000 | F96: 307 | G96: 1e+30 | H96: 17.5
... B156: $N$63 | C156: GWh Diciembre | D156: 300 | E156: -1390870 | F156: 300 | G156: 18.134715 | H156: 278.77

Sheet PL MULT. AS-TMAX
A2: PROGRAMACIÓN LINEAL MULTIPERIODO- TUCUMÁN 2027
A5: Variables de decision
A6: Variable | B6: Unidad | C6: Enero | D6: Febrero | E6: Marzo | F6: Abril | G6: Mayo | H6: Junio | I6: Julio | J6: Agosto | K6: Septiembre | L6: Octubre | M6: Noviembre | N6: Diciembre
A7: X_HIDRO (hidro <=50MW) | B7: GWh | C7: 14.82 | D7: 14.84 | E7: 27.58 | F7: 18.15 | G7: 8.33 | H7: 6.01 | I7: 6.18 | J7: 7.81 | K7: 10.24 | L7: 13.91 | M7: 17.78 | N7: 19.7
A8: X_BIOMASA (renov. biomasa) | B8: GWh | C8: 0 | D8: 0 | E8: 0 | F8: 0.54 | G8: 5.92 | H8: 11.49 | I8: 10.67 | J8: 10.17 | K8: 8.07 | L8: 7.47 | M8: 4.82 | N8: 0.91
A9: X_BIOGAS (renov. biogás) | B9: GWh | C9: 0.42 | D9: 0.4 | E9: 0.64 | F9: 1.03 | G9: 1.99 | H9: 2.05 | I9: 1.93 | J9: 1.99 | K9: 1.41 | L9: 0.69 | M9: 0.67 | N9: 0.62
A10: Y (energía convencional MEM) | B10: GWh | C10: 284.76 | D10: 275.95171 | E10: 256.75409 | F10: 199.96912 | G10: 217.95689 | H10: 232.26347 | I10: 247.54124 | J10: 217.3357 | K10: 206.18674 | L10: 234.92482 | M10: 257.55902 | N10: 278.77
A11: R (reserva térmica contratada) | B11: GWh | C11: 43.731522 | D11: 45.017144 | E11: 50.554353 | F11: 43.050761 | G11: 42.619605 | H11: 43.296488 | I11: 42.43294 | J11: 42.218665 | K11: 42.191476 | L11: 42.758041 | M11: 44.175761 | N11: 45.111472
A12: ENS (Energía No Suministrada) | B12: GWh | C12: 23.5 | D12: 0 | E12: 0 | F12: 0 | G12: 0 | H12: 0 | I12: 0 | J12: 0 | K12: 0 | L12: 0 | M12: 0 | N12: 17.5
A16: Función Objetivo
A17: Parámetro | B17: Unidad | C17: Enero | D17: Febrero | E17: Marzo | F17: Abril | G17: Mayo | H17: Junio | I17: Julio | J17: Agosto | K17: Septiembre | L17: Octubre | M17: Noviembre | N17: Diciembre
A18: Costo Mensual total | B18: UDS | C18: =$B$72*C7+$B$73*C8+$B$74*C9+C78*C10+$B$75*C11+$B$76*C12 -> 57362541 | D18: =$B$72*D7+$B$73*D8+$B$74*D9+D78*D10+$B$75*D11+$B$76*D12 -> 21156997 | E18: =$B$72*E7+$B$73*E8+$B$74*E9+E78*E10+$B$75*E11+$B$76*E12 -> 21141122 | F18: =$B$72*F7+$B$73*F8+$B$74*F9+F78*F10+$B$75*F11+$B$76*F12 -> 16233008 | G18: =$B$72*G7+$B$73*G8+$B$74*G9+G78*G10+$B$75*G11+$B$76*G12 -> 20629795 | H18: =$B$72*H7+$B$73*H8+$B$74*H9+H78*H10+$B$75*H11+$B$76*H12 -> 24974371 | I18: =$B$72*I7+$B$73*I8+$B$74*I9+I78*I10+$B$75*I11+$B$76*I12 -> 25540464 | J18: =$B$72*J7+$B$73*J8+$B$74*J9+J78*J10+$B$75*J11+$B$76*J12 -> 20330047 | ... N18: =$B$72*N7+$B$73*N8+$B$74*N9+N78*N10+$B$75*N11+$B$76*N12 -> 44319438
A20: Costo total anual | B20: UDS | C20: =SUM(C18:N18) -> 3.061601e+08
A23: Restricciones
A25: Balance de energía
B26: Unidad | C26: Enero | D26: Febrero | E26: Marzo | F26: Abril | G26: Mayo | H26: Junio | I26: Julio | J26: Agosto | K26: Septiembre | L26: Octubre | M26: Noviembre | N26: Diciembre
A27: LHS | B27: GWh | C27: =(1-$B$83)*(C7+C8+C9+C10)+C12 -> 313 | D27: =(1-$B$83)*(D7+D8+D9+D10)+D12 -> 281 | E27: =(1-$B$83)*(E7+E8+E9+E10)+E12 -> 275 | F27: =(1-$B$83)*(F7+F8+F9+F10)+F12 -> 212 | G27: =(1-$B$83)*(G7+G8+G9+G10)+G12 -> 226 | H27: =(1-$B$83)*(H7+H8+H9+H10)+H12 -> 243 | I27: =(1-$B$83)*(I7+I8+I9+I10)+I12 -> 257 | J27: =(1-$B$83)*(J7+J8+J9+J10)+J12 -> 229 | ... N27: =(1-$B$83)*(N7+N8+N9+N10)+N12 -> 307
A28: SIGNO | C28: = | D28: = | E28: = | F28: = | G28: = | H28: = | I28: = | J28: = | K28: = | L28: = | M28: = | N28: =
A29: RHS= D_t | B29: GWh | C29: 313 | D29: 281 | E29: 275 | F29: 212 | G29: 226 | H29: 243 | I29: 257 | J29: 229 | K29: 218 | L29: 248 | M29: 271 | N29: 307
A31: Stock de seguridad
B32: Unidad | C32: Enero | D32: Febrero | E32: Marzo | F32: Abril | G32: Mayo | H32: Junio | I32: Julio | J32: Agosto | K32: Septiembre | L32: Octubre | M32: Noviembre | N32: Diciembre
A33: LHS=R_t | B33: GWh | C33: =C11 -> 43.731522 | D33: =D11 -> 45.017144 | E33: =E11 -> 50.554353 | F33: =F11 -> 43.050761 | G33: =G11 -> 42.619605 | H33: =H11 -> 43.296488 | I33: =I11 -> 42.43294 | J33: =J11 -> 42.218665 | ... N33: =N11 -> 45.111472
A34: SIGNO | C34: >= | D34: >= | E34: >= | F34: >= | G34: >= | H34: >= | I34: >= | J34: >= | K34: >= | L34: >= | M34: >= | N34: >=
